Workbook

Sheet Explicação indicadores
B2: Domínios e seus respectivos indicadores | C2: Fonte | D2: Explicação
A3: Caminhabilidade | B3: Domicílios com calçada na rua de acesso | C3: PDAD-A 2024 | D3: Infraestrutura urbana no entorno dos domicílios: percentual de domicílios cuja rua de acesso principal é asfaltada.
B4: Calçadas com rampa para cadeirantes | C4: PDAD-A 2024 | D4: Infraestrutura urbana no entorno dos domicílios: percentual de domicílios com disponibilidade de rampas de acessibilidade para cadeirantes nas calçadas de acesso nas proximidades.
B5: Travessia sinalizada para pedestres | C5: PDAD-A 2024 | D5: Infraestrutura urbana no entorno dos domicílios: percentual de domicílios com presença de travessia sinalizada para pedestres (faixas, passarelas, passagens subterrâneas ou semáforos) nas proximidades.
B6: Qualidade da calçada | C6: PDAD-A 2024 | D6: Infraestrutura urbana existente nas proximidades dos domicílios: ponderação para uma avaliação qualitativa das calçadas (adotou-se um critério de ponderação progressiva: atribuiu-se peso 1,00 para a classificação “ótima”; 0,75 para “boa”; 0,50 para “regular”; 0,25 para “ruim” e 0,00 para “péssima”). O valor final do indicador corresponde, portanto, à soma ponderada das frequências percentuais de cada categoria.
A7: Ciclabilidade | B7: Presença de ciclofaixas ou ciclovias nas proximidades | C7: PDAD-A 2024 | D7: Infraestrutura urbana no entorno dos domicílios: percentual de domicílios com presença de ciclofaixas ou ciclovias em suas adjacências.
B8: Uso da bicicleta como principal meio de transporte para deslocamento ao trabalho | C8: Fig. 34
B9: Extensão da malha cicloviária (densidade km/km²) | C9: SEMOB | D9: Relação entre a extensão da malha cicloviária (km) e a área total de cada RA (km²) - resultados parametrizados com uma normalização dos dados baseada na densidade de infraestrutura, corrigido por uma função logarítmica.
B10: Pontos de aluguel de bicicleta compartilhada (Tem bici) (escala logarítmica) | C10: Tem Bici | D10: Levantamento de quantidade de estações em cada RA - resultados normalizados em uma escala de 0 a 1, com aplicação de função logarítmica e atribuição do valor 1 à Região Administrativa com o maior número de estações.
A11: Transporte público | B11: Uso de transporte público (ônibus + metrô) como principal meio de transporte para deslocamento ao trabalho | C11: PDAD-A 2024 | D11: Percentual de domicílios cujos moradores utilizam predominantemente ônibus ou metrô no deslocamento para o trabalho.
B12: Uso de transporte público (ônibus + escolar público + metrô) como principal meio de transporte para deslocamento à escola | C12: PDAD-A 2024 | D12: Percentual de domicílios cujos moradores utilizam predominantemente ônibus (regular ou escolar público) ou metrô no deslocamento para a escola.
B13: Densidade de pontos/paradas de ônibus por km2 (escala logarítmica) | C13: SEMOB (GeoServer) | D13: Relação entre a quantidade de pontos/paradas de ônibus (unid) e a área total de cada RA (km²) - resultados normalizados em uma escala de 0 a 1, baseados na densidade de infraestrutura, com aplicação de função logarítmica e atribuição do valor 1 à Região Administrativa com o maior número de pontos/paradas por km².
B14: Densidade de estações de metrô por km2 (escala logarítmica) | C14: GeoPortal | D14: Relação entre a quantidade de estações de metrô (unid) e a área total de cada RA (km²) - resultados normalizados em uma escala de 0 a 1, baseados na densidade de infraestrutura, com aplicação de função logarítmica e atribuição do valor 1 à Região Administrativa com o maior número de pontos/paradas por km².
A15: Proximidade Territorial | B15: Concentração de Vínculo Laboral na RA de residência (Trabalho na mesma RA da residência) | C15: PDAD-A 2024 | D15: Percentual de domicílios cujos moradores trabalham na mesma Região Administrativa (RA) em que residem.
B16: Taxa de atendimento em saúde na RA de residência (Último atendimento em saúde na mesma RA da residência) | C16: PDAD-A 2024 | D16: Percentual de domicílios cujos moradores buscaram atendimento em saúde, na última ocorrência, na mesma Região Administrativa (RA) em que residem.
B17: Predominância de compra de alimentos na RA de residência (Realiza as principais compras de alimentação na mesma RA da residência) | C17: PDAD-A 2024 | D17: Percentual de domicílios cujos moradores realizam a compra predominante de alimentos na mesma Região Administrativa (RA) em que residem.
B18: Walk Score | C18: Walkscore | D18: É um indicador internacional que mede o nível de caminhabilidade de um endereço — ou seja, o quanto é possível realizar atividades do dia a dia a pé, sem depender do carro. Ele avalia a proximidade de serviços, como restaurantes, mercados, farmácias, escolas, parques e centros comerciais, atribuindo uma pontuação que revela o grau de conveniência daquela localização.
A19: Aspectos ambientais | B19: Emissões do deslocamento/hab relativas às viagens por trabalho ou estudo | C19: IPE-DF (Avaliação de emissões de Gases de Efeito Estufa - Relatório 2) | D19: Emissões do deslocamento/hab relativas às viagens por trabalho ou estudo - RA por habitante (kgCO2/hab-ano) - resultados normalizados em uma escala de 0 a 1, com aplicação de função logarítmica e atribuição do valor 0 à Região Administrativa com a maior quantidade de emissões de deslocamento por habitante.
B20: Ruas arborizadas nas proximidades | C20: PDAD-A 2024 | D20: Infraestrutura urbana no entorno dos domicílios: percentual de domicílios que dispõem de ruas arborizadas nas suas adjacências.
B21: Disponibilidade de parques ou praças nas cercanias do domicílio (acesso a praças ou parques nas proximidades) | C21: PDAD-A 2024 | D21: Infraestrutura urbana no entorno dos domicílios: percentual de domicílios com a acesso a praças ou parques nas proximidades.

Sheet Resultados
B1: Domínios e seus respectivos indicadores | D1: RA I | E1: RA II | F1: RA III | G1: RA IV | H1: RA V | I1: RA VI | J1: RA VII | K1: RA VIII | L1: RA IX | M1: RA X | N1: RA XI | O1: RA XII | P1: RA XIII | Q1: RA XIV | R1: RA XV | S1: RA XVI | T1: RA XVII | U1: RA XVIII | V1: RA XIX | W1: RA XX | X1: RA XXI | Y1: RA XXII | Z1: RA XXIII | AA1: RA XXIV | AB1: RA XXV | AC1: RA XXVI | AD1: RA XXVII | AE1: RA XXVIII | AF1: RA XXIX | AG1: RA XXX | AH1: RA XXXI | AI1: RA XXXII | AJ1: RA XXXIII | AK1: RA XXXIV | AL1: RA XXXV
D2: Plano Piloto | E2: Gama | F2: Taguatinga | G2: Brazlândia | H2: Sobradinho | I2: Planaltina | J2: Paranoá | K2: Nucleo Bandeirante | L2: Ceilândia | M2: Guará | N2: Cruzeiro | O2: Samambaia | P2: Santa Maria | Q2: São Sebastião | R2: Recanto das Emas | S2: Lago Sul | T2: Riacho Fundo | U2: Lago Norte | V2: Candangolândia | W2: Águas Claras | X2: Riacho Fundo II | Y2: Sudoeste - Octogonal | Z2: Varjão | AA2: Parkway | AB2: SCIA - Estrutural | AC2: Sobradinho II | AD2: Jardim Botânico | AE2: Itapoã | AF2: SIA | AG2: Vicente Pires | AH2: Fercal | AI2: Sol Nascente e Pôr do Sol | AJ2: Arniqueira | AK2: Arapoanga | AL2: Água Quente
B3: Área em km² | C3: GeoPortal | D3: 437.20138 | E3: 276.05341 | F3: 63.044563 | G3: 470.18356 | H3: 193.52648 | I3: 1509.4149 | J3: 831.20985 | K3: 5.0468103 | L3: 192.65694 | M3: 25.22335 | N3: 3.1911636 | O3: 99.992287 | P3: 131.58309 | Q3: 262.70517 | R3: 93.106375 | S3: 76.04873 | T3: 17.781115 | U3: 75.491719 | V3: 6.6018644 | W3: 9.186564 | X3: 38.467155 | Y3: 6.4674366 | Z3: 1.6294368 | AA3: 118.40557 | AB3: 7.3865868 | AC3: 181.35209 | AD3: 291.42756 | AE3: 34.301568 | AF3: 29.050896 | AG3: 42.878036 | AH3: 154.38003 | AI3: 40.491664 | AJ3: 13.358497 | AK3: 21.985816 | AL3: 9.5121341
B4: População | C4: PDAD | D4: 207996 | E4: 133948 | F4: 201332 | G4: 41859 | H4: 70608 | I4: 121856 | J4: 55551 | K4: 22566 | L4: 287113 | M4: 127952 | N4: 26435 | O4: 227118 | P4: 121635 | Q4: 99050 | R4: 105862 | S4: 27213 | T4: 41040 | U4: 43817 | V4: 14540 | W4: 141872 | X4: 70180 | Y4: 46004 | Z4: 9017 | AA4: 22667 | AB4: 38047 | AC4: 79932 | AD4: 75133 | AE4: 67021 | AF4: 5630 | AG4: 105062 | AH4: 9141 | AI4: 108713 | AJ4: 44774 | AK4: 49067 | AL4: 11306
A5: Caminhabilidade | B5: Domicílios com calçada na rua de acesso | C5: Fig. 49 | D5: 0.95 | E5: 0.88 | F5: 0.946 | G5: 0.942 | H5: 0.777 | I5: 0.171 | J5: 0.944 | K5: 0.772 | L5: 0.88 | M5: 0.819 | N5: 0.962 | O5: 0.893 | P5: 0.891 | Q5: 0.556 | R5: 0.653 | S5: 0.91 | T5: 0.919 | U5: 0.613 | V5: 0.826 | W5: 0.995 | X5: 0.945 | Y5: 0.932 | Z5: 0.719 | AA5: 0.569 | AB5: 0.637 | AC5: 0.142 | AD5: 0.8 | AE5: 0.843 | AF5: 0.387 | AG5: 0.659 | AH5: 0.262 | AI5: 0.559 | AJ5: 0.737 | AK5: 0.187 | AL5: 0.385
B6: Calçadas com rampa para cadeirantes | C6: Fig. 49 | D6: 0.657 | E6: 0.409 | F6: 0.388 | G6: 0.391 | H6: 0.505 | I6: 0.532 | J6: 0.374 | K6: 0.451 | L6: 0.734 | M6: 0.469 | N6: 0.284 | O6: 0.457 | P6: 0.465 | Q6: 0.575 | R6: 0.359 | S6: 0.455 | T6: 0.446 | U6: 0.15 | V6: 0.345 | W6: 0.775 | X6: 0.617 | Y6: 0.678 | Z6: 0.398 | AA6: 0.577 | AB6: 0.284 | AC6: 0.815 | AD6: 0.592 | AE6: 0.524 | AF6: 0.103 | AG6: 0.355 | AH6: 0.248 | AI6: 0.211 | AJ6: 0.225 | AK6: 0.368 | AL6: 0.188
B7: Travessia sinalizada para pedestres | C7: Fig. 51 | D7: 0.884 | E7: 0.58 | F7: 0.747 | G7: 0.489 | H7: 0.581 | I7: 0.378 | J7: 0.894 | K7: 0.765 | L7: 0.875 | M7: 0.736 | N7: 0.784 | O7: 0.611 | P7: 0.576 | Q7: 0.406 | R7: 0.613 | S7: 0.627 | T7: 0.671 | U7: 0.558 | V7: 0.752 | W7: 0.948 | X7: 0.743 | Y7: 0.995 | Z7: 0.403 | AA7: 0.363 | AB7: 0.132 | AC7: 0.398 | AD7: 0.564 | AE7: 0.464 | AF7: 0.34 | AG7: 0.182 | AH7: 0.102 | AI7: 0.095 | AJ7: 0.318 | AK7: 0.132 | AL7: 0.212
B8: Qualidade da calçada | C8: Fig. 49 | D8: =6.4%+35.9%*0.75+28.8%*0.5+16.5%*0.25 -> 0.5185 | E8: =30.3%*0.75+34%*0.5+16.3%*0.25 -> 0.438 | F8: =21%*0.75+45%*0.5+17%*0.25 -> 0.425 | G8: =27.4%*0.75+34.6%*0.5+18.9%*0.25 -> 0.42575 | H8: =6.7%+33.1%*0.75+33.8%*0.5+14.2%*0.25 -> 0.51975 | I8: =43%*0.75+34.2%*0.5 -> 0.4935 | J8: =34.2%*0.75+26.3%*0.5+13.5%*0.25 -> 0.42175 | K8: =22.2%*0.75+38.2%*0.5+13.8%*0.25 -> 0.392 | L8: =18.9%*0.75+40.2%*0.5+18.3%*0.25 -> 0.3885 | M8: =26.6%*0.75+37.6%*0.5+13.7%*0.25 -> 0.42175 | N8: =32.6%*0.75+35.2%*0.5+13.3%*0.25 -> 0.45375 | O8: =30.1%*0.75+36.8%*0.5+15.9%*0.25 -> 0.4495 | P8: =34.2%*0.75+40.2%*0.5+8%*0.25 -> 0.4775 | Q8: =31.3%*0.75+41.1%*0.5+14%*0.25 -> 0.47525 | R8: =50.2%*0.75+29.4%*0.5+11.3%*0.25 -> 0.55175 | S8: =45.1%*0.75+27.5%*0.5+14.6%*0.25 -> 0.51225 | T8: =3.7%+28.8%*0.75+35.9%*0.5+17.6%*0.25 -> 0.4765 | U8: =67.9%*0.75+18.3%*0.5+6.9%*0.25 -> 0.618 | V8: =37%*0.75+36.1%*0.5+12%*0.25 -> 0.488 | W8: =43.9%*0.75+35.8%*0.5+13%*0.25 -> 0.54075 | X8: =4.2%+43%*0.75+34.8%*0.5+9.5%*0.25 -> 0.56225 | Y8: =4.9%+48.4%*0.75+25.5%*0.5+12.8%*0.25 -> 0.5715 | Z8: =36.2%*0.75+38.6%*0.5+17.1%*0.25 -> 0.50725 | AA8: =8.9%+49.8%*0.75+26.2%*0.5+7.6%*0.25 -> 0.6125 | AB8: =27.1%*0.75+32.1%*0.5+19.4%*0.25 -> 0.41225 | AC8: =51.3%*0.75+30%*0.5 -> 0.53475 | AD8: =10.8%+44.1%*0.75+29.2%*0.5+9.8%*0.25 -> 0.60925 | AE8: =32.5%*0.75+43.8%*0.5+13.7%*0.25 -> 0.497 | AF8: =31.6%*0.75+38.6%*0.5 -> 0.43 | AG8: =6.6%+48.4%*0.75+30.3%*0.5+9.3%*0.25 -> 0.60375 | AH8: =25.2%*0.75+42.7%*0.5+18.4%*0.25 -> 0.4485 | AI8: =34.7%*0.75+28.3%*0.5+13.7%*0.25 -> 0.436 | AJ8: =3.9%+19.1%*0.75+30.8%*0.5+21.9%*0.25 -> 0.391 | AK8: =36.2%*0.75+27.7%*0.5+18.1%*0.25 -> 0.45525 | AL8: =35.1%*0.75+35.7%*0.5 -> 0.44175
A9: Ciclabilidade | B9: Presença de ciclofaixas ou ciclovias nas proximidades | C9: Fig. 51 | D9: 0.78 | E9: 0.56 | F9: 0.333 | G9: 0.213 | H9: 0.288 | I9: 0.227 | J9: 0.761 | K9: 0.732 | L9: 0.712 | M9: 0.685 | N9: 0.717 | O9: 0.501 | P9: 0.623 | Q9: 0.393 | R9: 0.684 | S9: 0.629 | T9: 0.455 | U9: 0.474 | V9: 0.69 | W9: 0.873 | X9: 0.713 | Y9: 0.947 | Z9: 0.328 | AA9: 0.707 | AB9: 0.136 | AC9: 0.161 | AD9: 0.591 | AE9: 0.411 | AF9: 0.327 | AG9: 0.234 | AH9: 0.032 | AI9: 0.1 | AJ9: 0.253 | AK9: 0.206 | AL9: 0.143
B10: Uso da bicicleta como principal meio de transporte para deslocamento ao trabalho | C10: Fig. 34 | D10: 0 | E10: 0 | F10: 0 | G10: 0 | H10: 0 | I10: 0 | J10: 0 | K10: 0 | L10: 0.026 | M10: 0 | N10: 0 | O10: 0 | P10: 0 | Q10: 0.025 | R10: 0 | S10: 0 | T10: 0 | U10: 0 | V10: 0 | W10: 0 | X10: 0 | Y10: 0 | Z10: 0 | AA10: 0 | AB10: 0.157 | AC10: 0 | AD10: 0 | AE10: 0 | AF10: 0.133 | AG10: 0 | AH10: 0 | AI10: 0.049 | AJ10: 0.038 | AK10: 0.064 | AL10: 0
B11: Extensão da malha cicloviária (km) (OCULTAR) | C11: SEMOB | D11: 144.906 | E11: 39.111 | F11: 15.566 | G11: 6.279 | H11: 11.357 | I11: 17.095 | J11: 29.408 | K11: 5.527 | L11: 51.977 | M11: 27.199 | N11: 0 | O11: 23.506 | P11: 35.801 | Q11: 11.771 | R11: 28.668 | S11: 59.464 | T11: 1.19 | U11: 33.907 | V11: 1.371 | W11: 25.065 | X11: 22.868 | Y11: 12.091 | Z11: 0.617 | AA11: 51.035 | AB11: 1.969 | AC11: 22.025 | AD11: 26.111 | AE11: 9.131 | AF11: 5.261 | AG11: 17.823 | AH11: 2.513 | AI11: 0 | AJ11: 2.555 | AK11: 1.47 | AL11: 0
B12: Extensão da malha cicloviária (densidade) (OCULTAR) | C12: SEMOB | D12: =D11/D3 -> 0.33143994 | E12: =E11/E3 -> 0.1416791 | F12: =F11/F3 -> 0.24690472 | G12: =G11/G3 -> 0.013354359 | H12: =H11/H3 -> 0.058684476 | I12: =I11/I3 -> 0.011325581 | J12: =J11/J3 -> 0.035379754 | K12: =K11/K3 -> 1.0951472 | ... AL12: =AL11/AL3 -> 0
B13: Extensão da malha cicloviária (Dx / Dmáx) | C13: SEMOB | D13: =D12/$W$12 -> 0.12147593 | E13: =E12/$W$12 -> 0.051926756 | F13: =F12/$W$12 -> 0.090492958 | G13: =G12/$W$12 -> 0.0048945012 | H13: =H12/$W$12 -> 0.021508426 | I13: =I12/$W$12 -> 0.0041509344 | J13: =J12/$W$12 -> 0.012967021 | K13: =K12/$W$12 -> 0.40138199 | ... AL13: =AL12/$W$12 -> 0
B14: Extensão da malha cicloviária (escala logarítmica) | C14: SEMOB | D14: =LOG(D12+1,10)/LOG($W$12+1) -> 0.21752518 | E14: =LOG(E12+1,10)/LOG($W$12+1) -> 0.10068469 | F14: =LOG(F12+1,10)/LOG($W$12+1) -> 0.16767925 | G14: =LOG(G12+1,10)/LOG($W$12+1) -> 0.010080603 | H14: =LOG(H12+1,10)/LOG($W$12+1) -> 0.043333967 | I14: =LOG(I12+1,10)/LOG($W$12+1) -> 0.0085577583 | J14: =LOG(J12+1,10)/LOG($W$12+1) -> 0.026419855 | K14: =LOG(K12+1,10)/LOG($W$12+1) -> 0.56202833 | ... AL14: =LOG(AL12+1,10)/LOG($W$12+1) -> 0
B15: Pontos de aluguel de bicicleta compartilhada (Tem bici) quantidade de estações (OCULTAR) | C15: Tem Bici | D15: 64 | E15: 0 | F15: 0 | G15: 0 | H15: 0 | I15: 0 | J15: 0 | K15: 0 | L15: 0 | M15: 0 | N15: 0 | O15: 0 | P15: 0 | Q15: 0 | R15: 0 | S15: 0 | T15: 0 | U15: 0 | V15: 0 | W15: 0 | X15: 0 | Y15: 6 | Z15: 0 | AA15: 0 | AB15: 0 | AC15: 0 | AD15: 0 | AE15: 0 | AF15: 0 | AG15: 0 | AH15: 0 | AI15: 0 | AJ15: 0 | AK15: 0 | AL15: 0
B16: Pontos de aluguel de bicicleta compartilhada (Tem bici) (Dx / Dmáx) | C16: Tem Bici | D16: =D15/$D$15 -> 1 | E16: =E15/$D$15 -> 0 | F16: =F15/$D$15 -> 0 | G16: =G15/$D$15 -> 0 | H16: =H15/$D$15 -> 0 | I16: =I15/$D$15 -> 0 | J16: =J15/$D$15 -> 0 | K16: =K15/$D$15 -> 0 | ... AL16: =AL15/$D$15 -> 0
B17: Pontos de aluguel de bicicleta compartilhada (Tem bici) (escala logarítmica) | C17: Tem Bici | D17: =IF(D15>0,LOG(D15+1,10)/LOG($D$15+1),0) -> 1 | E17: =IF(E15>0,LOG(E15+1,10)/LOG($D$15+1),0) -> 0 | F17: =IF(F15>0,LOG(F15+1,10)/LOG($D$15+1),0) -> 0 | G17: =IF(G15>0,LOG(G15+1,10)/LOG($D$15+1),0) -> 0 | H17: =IF(H15>0,LOG(H15+1,10)/LOG($D$15+1),0) -> 0 | I17: =IF(I15>0,LOG(I15+1,10)/LOG($D$15+1),0) -> 0 | J17: =IF(J15>0,LOG(J15+1,10)/LOG($D$15+1),0) -> 0 | K17: =IF(K15>0,LOG(K15+1,10)/LOG($D$15+1),0) -> 0 | ... AL17: =IF(AL15>0,LOG(AL15+1,10)/LOG($D$15+1),0) -> 0
A18: Transporte público | B18: Uso do ônibus como principal meio de transporte para deslocamento ao trabalho (OCULTAR) | C18: Fig. 34 | D18: 0.129 | E18: 0.31 | F18: 0.275 | G18: 0.372 | H18: 0.277 | I18: 0.388 | J18: 0.483 | K18: 0.293 | L18: 0.361 | M18: 0.159 | N18: 0.162 | O18: 0.369 | P18: 0.596 | Q18: 0.533 | R18: 0.521 | S18: 0 | T18: 0.368 | U18: 0.122 | V18: 0.319 | W18: 0.058 | X18: 0.495 | Y18: 0.09 | Z18: 0.43 | AA18: 0.048 | AB18: 0.402 | AC18: 0.378 | AD18: 0.138 | AE18: 0.506 | AF18: 0.237 | AG18: 0.19 | AH18: 0.4 | AI18: 0.46 | AJ18: 0.223 | AK18: 0.561 | AL18: 0.471
B19: Uso do metrô como principal meio de transporte para deslocamento ao trabalho (OCULTAR) | C19: Fig. 34 | D19: 0 | E19: 0 | F19: 0 | G19: 0 | H19: 0 | I19: 0 | J19: 0 | K19: 0 | L19: 0.065 | M19: 0 | N19: 0 | O19: 0.078 | P19: 0 | Q19: 0 | R19: 0 | S19: 0 | T19: 0 | U19: 0 | V19: 0 | W19: 0.172 | X19: 0 | Y19: 0 | Z19: 0 | AA19: 0 | AB19: 0 | AC19: 0 | AD19: 0 | AE19: 0 | AF19: 0 | AG19: 0 | AH19: 0 | AI19: 0 | AJ19: 0 | AK19: 0 | AL19: 0
B20: Uso de transporte público (ônibus + metrô) como principal meio de transporte para deslocamento ao trabalho | C20: Fig. 34 | D20: =D18+D19 -> 0.129 | E20: =E18+E19 -> 0.31 | F20: =F18+F19 -> 0.275 | G20: =G18+G19 -> 0.372 | H20: =H18+H19 -> 0.277 | I20: =I18+I19 -> 0.388 | J20: =J18+J19 -> 0.483 | K20: =K18+K19 -> 0.293 | ... AL20: =AL18+AL19 -> 0.471
B21: Uso do ônibus + transporte escolar público como principal meio de transporte para deslocamento à escola (OCULTAR) | C21: Fig. 25 | D21: 0.145 | E21: 0.187 | F21: 0.241 | G21: 0.218 | H21: 0.207 | I21: 0.27 | J21: =0.356+0.161 -> 0.517 | K21: 0.286 | L21: 0.213 | M21: 0.206 | N21: 0.23 | O21: 0.273 | P21: 0.269 | Q21: =0.332+0.141 -> 0.473 | R21: 0.265 | S21: 0 | T21: =0.245+0.092 -> 0.337 | U21: 0.15 | V21: 0.184 | W21: 0 | X21: =0.438+0.119 -> 0.557 | Y21: 0 | Z21: =0.285+0.252 -> 0.537 | AA21: 0.079 | AB21: =0.463+0.203 -> 0.666 | AC21: 0.396 | AD21: 0.157 | AE21: =0.439+0.218 -> 0.657 | AF21: =0.305+0.295 -> 0.6 | AG21: =0.28+0.224 -> 0.504 | AH21: =0.421+0.284 -> 0.705 | AI21: 0.303 | AJ21: =0.217+0.092 -> 0.309 | AK21: =0.323+0.119 -> 0.442 | AL21: =0.384+0.187 -> 0.571
B22: Uso do metrô como principal meio de transporte para deslocamento à escola (OCULTAR) | C22: Fig. 25 | D22: 0 | E22: 0 | F22: 0 | G22: 0 | H22: 0 | I22: 0 | J22: 0 | K22: 0 | L22: 0 | M22: 0 | N22: 0 | O22: 0 | P22: 0 | Q22: 0 | R22: 0 | S22: 0 | T22: 0 | U22: 0 | V22: 0 | W22: 0.12 | X22: 0 | Y22: 0 | Z22: 0 | AA22: 0 | AB22: 0 | AC22: 0 | AD22: 0 | AE22: 0 | AF22: 0 | AG22: 0 | AH22: 0 | AI22: 0 | AJ22: 0 | AK22: 0 | AL22: 0
B23: Uso de transporte público (ônibus + escolar público + metrô) como principal meio de transporte para deslocamento à escola | C23: Fig. 25 | D23: =D21+D22 -> 0.145 | E23: =E21+E22 -> 0.187 | F23: =F21+F22 -> 0.241 | G23: =G21+G22 -> 0.218 | H23: =H21+H22 -> 0.207 | I23: =I21+I22 -> 0.27 | J23: =J21+J22 -> 0.517 | K23: =K21+K22 -> 0.286 | ... AL23: =AL21+AL22 -> 0.571
B24: Quantidade de paradas de ônibus (OCULTAR) | C24: SEMOB (GeoServer) | D24: 562 | E24: 260 | F24: 296 | G24: 220 | H24: 185 | I24: 440 | J24: 219 | K24: 57 | L24: 507 | M24: 132 | N24: 38 | O24: 307 | P24: 253 | Q24: 144 | R24: 176 | S24: 161 | T24: 33 | U24: 110 | V24: 31 | W24: 41 | X24: 122 | Y24: 64 | Z24: 16 | AA24: 141 | AB24: 51 | AC24: 173 | AD24: 146 | AE24: 35 | AF24: 144 | AG24: 161 | AH24: 52 | AI24: 65 | AJ24: 73 | AK24: 30 | AL24: 11
B25: Densidade de pontos/paradas de ônibus por km2 (OCULTAR) | C25: SEMOB (GeoServer) | D25: =D24/D3 -> 1.2854488 | E25: =E24/E3 -> 0.94184671 | F25: =F24/F3 -> 4.6950916 | G25: =G24/G3 -> 0.46790237 | H25: =H24/H3 -> 0.95594155 | I25: =I24/I3 -> 0.29150368 | J25: =J24/J3 -> 0.26347137 | K25: =K24/K3 -> 11.294262 | ... AL25: =AL24/AL3 -> 1.1564177
B26: Densidade de pontos/paradas de ônibus por km2 (Dx / Dmáx) | C26: SEMOB (GeoServer) | D26: =D25/$N$25 -> 0.10794941 | E26: =E25/$N$25 -> 0.079094392 | F26: =F25/$N$25 -> 0.39428435 | G26: =G25/$N$25 -> 0.039293499 | H26: =H25/$N$25 -> 0.080278048 | I26: =I25/$N$25 -> 0.024479893 | J26: =J25/$N$25 -> 0.022125796 | K26: =K25/$N$25 -> 0.94846944 | ... AL26: =AL25/$N$25 -> 0.09711363
B27: Densidade de pontos/paradas de ônibus por km2 (escala logarítmica) | C27: SEMOB (GeoServer) | D27: =LOG(D25+1,10)/LOG($N$25+1) -> 0.32314884 | E27: =LOG(E25+1,10)/LOG($N$25+1) -> 0.25945325 | F27: =LOG(F25+1,10)/LOG($N$25+1) -> 0.68010741 | G27: =LOG(G25+1,10)/LOG($N$25+1) -> 0.15006204 | H27: =LOG(H25+1,10)/LOG($N$25+1) -> 0.26228074 | I27: =LOG(I25+1,10)/LOG($N$25+1) -> 0.10000914 | J27: =LOG(J25+1,10)/LOG($N$25+1) -> 0.091429941 | K27: =LOG(K25+1,10)/LOG($N$25+1) -> 0.98095835 | ... AL27: =LOG(AL25+1,10)/LOG($N$25+1) -> 0.30042884
B28: Quantidade de estações de metrô (OCULTAR) | C28: GeoPortal | D28: 10 | E28: 0 | F28: 4 | G28: 0 | H28: 0 | I28: 0 | J28: 0 | K28: 0 | L28: 5 | M28: 3 | N28: 0 | O28: 2 | P28: 0 | Q28: 0 | R28: 0 | S28: 0 | T28: 0 | U28: 0 | V28: 0 | W28: 4 | X28: 0 | Y28: 0 | Z28: 0 | AA28: 0 | AB28: 0 | AC28: 0 | AD28: 0 | AE28: 0 | AF28: 0 | AG28: 0 | AH28: 0 | AI28: 0 | AJ28: 0 | AK28: 0 | AL28: 0
B29: Densidade de estações de metrô por km2 (OCULTAR) | C29: GeoPortal | D29: =D28/D3 -> 0.022872755 | E29: =E28/E3 -> 0 | F29: =F28/F3 -> 0.063447184 | G29: =G28/G3 -> 0 | H29: =H28/H3 -> 0 | I29: =I28/I3 -> 0 | J29: =J28/J3 -> 0 | K29: =K28/K3 -> 0 | ... AL29: =AL28/AL3 -> 0
B30: Densidade de estações de metrô por km2 (Dx / Dmáx) | C30: GeoPortal | D30: =IF(D29>0,D29/$W$29,0) -> 0.052530507 | E30: =IF(E29>0,E29/$W$29,0) -> 0 | F30: =IF(F29>0,F29/$W$29,0) -> 0.14571541 | G30: =IF(G29>0,G29/$W$29,0) -> 0 | H30: =IF(H29>0,H29/$W$29,0) -> 0 | I30: =IF(I29>0,I29/$W$29,0) -> 0 | J30: =IF(J29>0,J29/$W$29,0) -> 0 | K30: =IF(K29>0,K29/$W$29,0) -> 0 | ... AL30: =IF(AL29>0,AL29/$W$29,0) -> 0
B31: Densidade de estações de metrô por km2 (escala logarítmica) | C31: GeoPortal | D31: =IF(D29>0,LOG(D29+1,10)/LOG($W$29+1),0) -> 0.062566583 | E31: =IF(E29>0,LOG(E29+1,10)/LOG($W$29+1),0) -> 0 | F31: =IF(F29>0,LOG(F29+1,10)/LOG($W$29+1),0) -> 0.17018839 | G31: =IF(G29>0,LOG(G29+1,10)/LOG($W$29+1),0) -> 0 | H31: =IF(H29>0,LOG(H29+1,10)/LOG($W$29+1),0) -> 0 | I31: =IF(I29>0,LOG(I29+1,10)/LOG($W$29+1),0) -> 0 | J31: =IF(J29>0,LOG(J29+1,10)/LOG($W$29+1),0) -> 0 | K31: =IF(K29>0,LOG(K29+1,10)/LOG($W$29+1),0) -> 0 | ... AL31: =IF(AL29>0,LOG(AL29+1,10)/LOG($W$29+1),0) -> 0
A32: Proximidade Territorial | B32: Concentração de Vínculo Laboral na RA de residência (Trabalho na mesma RA da residência) | C32: Fig. 29 | D32: 0.835 | E32: 0.478 | F32: 0.481 | G32: 0.534 | H32: 0.365 | I32: 0.484 | J32: 0.274 | K32: 0.256 | L32: 0.39 | M32: 0.225 | N32: 0.269 | O32: 0.345 | P32: 0.255 | Q32: 0.423 | R32: 0.318 | S32: 0.194 | T32: 0.279 | U32: 0.286 | V32: 0.305 | W32: 0.274 | X32: 0.197 | Y32: 0.36 | Z32: 0.226 | AA32: 0.223 | AB32: 0.288 | AC32: 0.357 | AD32: 0.222 | AE32: 0.295 | AF32: 0.406 | AG32: 0.35 | AH32: 0.467 | AI32: 0.139 | AJ32: 0.257 | AK32: =0.226+0.032 -> 0.258 | AL32: 0.263
B33: Taxa de atendimento em saúde na RA de residência (Último atendimento em saúde na mesma RA da residência) | C33: Fig. 21 | D33: 0.909 | E33: 0.716 | F33: 0.79 | G33: 0.709 | H33: 0.588 | I33: 0.738 | J33: 0.701 | K33: 0.356 | L33: 0.711 | M33: 0.29 | N33: 0.714 | O33: 0.569 | P33: 0.538 | Q33: 0.68 | R33: 0.613 | S33: 0.458 | T33: 0.301 | U33: 0.142 | V33: 0.427 | W33: 0.522 | X33: 0.427 | Y33: 0.363 | Z33: 0.602 | AA33: 0.087 | AB33: 0.49 | AC33: 0.633 | AD33: 0.116 | AE33: 0.392 | AF33: 0 | AG33: 0.265 | AH33: 0.593 | AI33: 0.46 | AJ33: 0.331 | AK33: 0.557 | AL33: 0.275
B34: Predominância de compra de alimentos na RA de residência (Realiza as principais compras de alimentação na mesma RA da residência) | C34: Fig. 59 | D34: 0.857 | E34: 0.925 | F34: 0.907 | G34: 0.735 | H34: 0.949 | I34: 0.969 | J34: 0.837 | K34: 0.604 | L34: 0.977 | M34: 0.806 | N34: 0.794 | O34: 0.913 | P34: 0.831 | Q34: 0.949 | R34: 0.96 | S34: 0.728 | T34: 0.769 | U34: 0.677 | V34: 0.497 | W34: 0.816 | X34: 0.558 | Y34: 0.593 | Z34: 0.409 | AA34: 0.186 | AB34: =0.658+0.037 -> 0.695 | AC34: 0.795 | AD34: 0.767 | AE34: 0.803 | AF34: 0.476 | AG34: 0.848 | AH34: 0.274 | AI34: 0.619 | AJ34: 0.634 | AK34: 0.797 | AL34: 0.27
B35: Walk Score | C35: Walkscore | D35: 0.98 | E35: 0.81 | F35: 0.99 | G35: 0.6 | H35: 0.62 | I35: 0.85 | J35: 0.71 | K35: 0.87 | L35: 0.88 | M35: 0.75 | N35: 0.75 | O35: 0.55 | P35: 0.64 | Q35: 0.77 | R35: 0.7 | S35: 0.47 | T35: 0.97 | U35: 0.87 | V35: 0.77 | W35: 0.89 | X35: 0.67 | Y35: 0.89 | Z35: 0.6 | AA35: 0.74 | AB35: 0.63 | AC35: 0.62 | AD35: 0.07 | AE35: 0.35 | AF35: 0.61 | AG35: 0.75 | AH35: 0.41 | AI35: 0.41 | AJ35: 0.83 | AK35: 0.64 | AL35: 0.34
A36: Aspectos ambientais | B36: Emissões do deslocamento/hab relativas às viagens por trabalho ou estudo (OCULTAR) | C36: IPE-DF (Avaliação de emissões de Gases de Efeito Estufa - Relatório 2 - gráfico 5) | D36: 441 | E36: 420 | F36: 420 | G36: 417 | H36: 780 | I36: 474 | J36: 184 | K36: 372 | L36: 151 | M36: 612 | N36: 275 | O36: 263 | P36: 756 | Q36: 154 | R36: 184 | S36: 1303 | T36: 397 | U36: 1267 | V36: 685 | W36: 660 | X36: 594 | Y36: 458 | Z36: 311 | AA36: 2065 | AB36: 84 | AC36: 1132 | AD36: 1879 | AE36: 536 | AF36: 702 | AG36: 747 | AH36: 365 | AI36: 129 | AJ36: 931
B37: Emissões do deslocamento/hab relativas às viagens por trabalho ou estudo | C37: IPE-DF (Avaliação de emissões de Gases de Efeito Estufa - Relatório 2 - gráfico 5) | D37: =ROUND(1 - (D36 / 2065),3) -> 0.786 | E37: =ROUND(1 - (E36 / 2065),3) -> 0.797 | F37: =ROUND(1 - (F36 / 2065),3) -> 0.797 | G37: =ROUND(1 - (G36 / 2065),3) -> 0.798 | H37: =ROUND(1 - (H36 / 2065),3) -> 0.622 | I37: =ROUND(1 - (I36 / 2065),3) -> 0.77 | J37: =ROUND(1 - (J36 / 2065),3) -> 0.911 | K37: =ROUND(1 - (K36 / 2065),3) -> 0.82 | ... AJ37: =ROUND(1 - (AJ36 / 2065),3) -> 0.549
B38: Ruas arborizadas nas proximidades | C38: Fig. 51 | D38: 0.982 | E38: 0.878 | F38: 0.856 | G38: 0.762 | H38: 0.764 | I38: 0.708 | J38: 0.81 | K38: 0.866 | L38: 0.871 | M38: 0.853 | N38: 0.957 | O38: 0.801 | P38: 0.634 | Q38: 0.743 | R38: 0.695 | S38: 0.927 | T38: 0.879 | U38: 0.911 | V38: 0.834 | W38: 0.883 | X38: 0.855 | Y38: 0.997 | Z38: 0.9 | AA38: 0.917 | AB38: 0.378 | AC38: 0.849 | AD38: 0.95 | AE38: 0.416 | AF38: 0.82 | AG38: 0.877 | AH38: 0.868 | AI38: 0.469 | AJ38: 0.709 | AK38: 0.613 | AL38: 0.448
B39: Disponibilidade de parques ou praças nas cercanias do domicílio (acesso a praças ou parques nas proximidades) | C39: Fig. 51 | D39: 0.883 | E39: 0.618 | F39: 0.754 | G39: 0.662 | H39: 0.512 | I39: 0.441 | J39: 0.795 | K39: 0.791 | L39: 0.877 | M39: 0.785 | N39: 0.92 | O39: 0.664 | P39: 0.625 | Q39: 0.451 | R39: 0.706 | S39: 0.662 | T39: 0.802 | U39: 0.635 | V39: 0.881 | W39: 0.918 | X39: 0.8 | Y39: 0.997 | Z39: 0.875 | AA39: 0.461 | AB39: 0.345 | AC39: 0.558 | AD39: 0.746 | AE39: 0.339 | AF39: 0.347 | AG39: 0.332 | AH39: 0.455 | AI39: 0.153 | AJ39: 0.472 | AK39: 0.171 | AL39: 0.305

Sheet Pesos
B2: Domínios e seus respectivos indicadores | C2: Especialista 1 | D2: Especialista 2 | E2: Especialista 3 | F2: Especialista 4 | G2: Especialista 5 | H2: Média aritmética
A3: Caminhabilidade | B3: Caminhabilidade | C3: 0.2327 | D3: 0.3171 | E3: 0.148 | F3: 0.097 | G3: 0.247 | H3: =SUM(C3:G3)/5 -> 0.20836
B4: Domicílios com calçada na rua de acesso | C4: 0.4874 | D4: 0.551 | E4: 0.072 | F4: 0.444 | G4: 0.5083 | H4: =SUM(C4:G4)/5 -> 0.41254
B5: Calçadas com rampa para cadeirantes | C5: 0.1182 | D5: 0.131 | E5: 0.072 | F5: 0.078 | G5: 0.1512 | H5: =SUM(C5:G5)/5 -> 0.11008
B6: Travessia sinalizada para pedestres | C6: 0.2762 | D6: 0.044 | E6: 0.167 | F6: 0.341 | G6: 0.0752 | H6: =SUM(C6:G6)/5 -> 0.18068
B7: Qualidade da calçada | C7: 0.1182 | D7: 0.274 | E7: 0.689 | F7: 0.137 | G7: 0.2653 | H7: =SUM(C7:G7)/5 -> 0.2967
A8: Ciclabilidade | B8: Ciclabilidade | C8: 0.0495 | D8: 0.0813 | E8: 0.031 | F8: 0.062 | G8: 0.102 | H8: =SUM(C8:G8)/5 -> 0.06516
B9: Presença de ciclofaixas ou ciclovias nas proximidades | C9: 0.4286 | D9: 0.637 | E9: 0.188 | F9: 0.649 | G9: 0.637 | H9: =SUM(C9:G9)/5 -> 0.50792
B10: Uso da bicicleta como principal meio de transporte para deslocamento ao trabalho | H10: =SUM(C10:G10)/5 -> 0
B11: Extensão da malha cicloviária (densidade km/km²) | C11: 0.4286 | D11: 0.258 | E11: 0.731 | F11: 0.279 | G11: 0.258 | H11: =SUM(C11:G11)/5 -> 0.39092
B12: Pontos de aluguel de bicicleta compartilhada (Tem bici) (escala logarítmica) | C12: 0.1428 | D12: 0.105 | E12: 0.081 | F12: 0.072 | G12: 0.105 | H12: =SUM(C12:G12)/5 -> 0.10116
A13: Transporte público | B13: Transporte público | C13: 0.3648 | D13: 0.1638 | E13: 0.139 | F13: 0.391 | G13: 0.337 | H13: =SUM(C13:G13)/5 -> 0.27912
B14: Uso de transporte público (ônibus + metrô) como principal meio de transporte para deslocamento ao trabalho | C14: 0.375 | D14: 0.125 | E14: 0.558 | F14: 0.083 | G14: 0.5083 | H14: =SUM(C14:G14)/5 -> 0.32986
B15: Uso de transporte público (ônibus + escolar público + metrô) como principal meio de transporte para deslocamento à escola | C15: 0.375 | D15: 0.125 | E15: 0.113 | F15: 0.083 | G15: 0.1512 | H15: =SUM(C15:G15)/5 -> 0.16944
B16: Densidade de pontos/paradas de ônibus por km2 (escala logarítmica) | C16: 0.125 | D16: 0.375 | E16: 0.279 | F16: 0.417 | G16: 0.2653 | H16: =SUM(C16:G16)/5 -> 0.29226
B17: Densidade de estações de metrô por km2 (escala logarítmica) | C17: 0.125 | D17: 0.375 | E17: 0.05 | F17: 0.417 | G17: 0.0752 | H17: =SUM(C17:G17)/5 -> 0.20844
A18: Proximidade Territorial | B18: Proximidade Territorial | C18: 0.2045 | D18: 0.0424 | E18: 0.628 | F18: 0.407 | G18: 0.244 | H18: =SUM(C18:G18)/5 -> 0.30518
B19: Concentração de Vínculo Laboral na RA de residência (Trabalho na mesma RA da residência) | C19: 0.4131 | D19: 0.146 | E19: 0.6223 | F19: 0.6208 | G19: 0.5495 | H19: =SUM(C19:G19)/5 -> 0.47034
B20: Taxa de atendimento em saúde na RA de residência (Último atendimento em saúde na mesma RA da residência) | C20: 0.1064 | D20: 0.093 | E20: 0.0603 | F20: 0.1654 | G20: 0.2476 | H20: =SUM(C20:G20)/5 -> 0.13454
B21: Predominância de compra de alimentos na RA de residência (Realiza as principais compras de alimentação na mesma RA da residência) | C21: 0.1201 | D21: 0.346 | E21: 0.1155 | F21: 0.1654 | G21: 0.0736 | H21: =SUM(C21:G21)/5 -> 0.16412
B22: Walk Score | C22: 0.3604 | D22: 0.415 | E22: 0.2019 | F22: 0.0484 | G22: 0.1293 | H22: =SUM(C22:G22)/5 -> 0.231
A23: Aspectos ambientais | B23: Aspectos ambientais | C23: 0.1485 | D23: 0.3954 | E23: 0.054 | F23: 0.043 | G23: 0.07 | H23: =SUM(C23:G23)/5 -> 0.14218
B24: Emissões do deslocamento/hab relativas às viagens por trabalho ou estudo | C24: 0.6 | D24: 0.081 | E24: 0.063 | F24: 0.105 | G24: 0.637 | H24: =SUM(C24:G24)/5 -> 0.2972
B25: Ruas arborizadas nas proximidades | C25: 0.2 | D25: 0.731 | E25: 0.672 | F25: 0.637 | G25: 0.258 | H25: =SUM(C25:G25)/5 -> 0.4996 | I25: =H25/(H26+H25) -> 0.7108708
B26: Disponibilidade de parques ou praças nas cercanias do domicílio (acesso a praças ou parques nas proximidades) | C26: 0.2 | D26: 0.188 | E26: 0.265 | F26: 0.258 | G26: 0.105 | H26: =SUM(C26:G26)/5 -> 0.2032 | I26: =H26/(H25+H26) -> 0.2891292

Sheet Resultados IMAP
B1: RA I | C1: RA II | D1: RA III | E1: RA IV | F1: RA V | G1: RA VI | H1: RA VII | I1: RA VIII | J1: RA IX | K1: RA X | L1: RA XI | M1: RA XII | N1: RA XIII | O1: RA XIV | P1: RA XV | Q1: RA XVI | R1: RA XVII | S1: RA XVIII | T1: RA XIX | U1: RA XX | V1: RA XXI | W1: RA XXII | X1: RA XXIII | Y1: RA XXIV | Z1: RA XXV | AA1: RA XXVI | AB1: RA XXVII | AC1: RA XXVIII | AD1: RA XXIX | AE1: RA XXX | AF1: RA XXXI | AG1: RA XXXII | AH1: RA XXXIII | AI1: RA XXXIV | AJ1: RA XXXV
B2: Plano Piloto | C2: Gama | D2: Taguatinga | E2: Brazlândia | F2: Sobradinho | G2: Planaltina | H2: Paranoá | I2: Nucleo Bandeirante | J2: Ceilândia | K2: Guará | L2: Cruzeiro | M2: Samambaia | N2: Santa Maria | O2: São Sebastião | P2: Recanto das Emas | Q2: Lago Sul | R2: Riacho Fundo | S2: Lago Norte | T2: Candangolândia | U2: Águas Claras | V2: Riacho Fundo II | W2: Sudoeste - Octogonal | X2: Varjão | Y2: Parkway | Z2: SCIA - Estrutural | AA2: Sobradinho II | AB2: Jardim Botânico | AC2: Itapoã | AD2: SIA | AE2: Vicente Pires | AF2: Fercal | AG2: Sol Nascente e Pôr do Sol | AH2: Arniqueira | AI2: Arapoanga | AJ2: Água Quente
A3: Caminhabilidade | B3: =Resultados!D5*Pesos!$H$4+Resultados!D6*Pesos!$H$5+Resultados!D7*Pesos!$H$6+Resultados!D8*Pesos!$H$7 -> 0.77779563 | C3: =Resultados!E5*Pesos!$H$4+Resultados!E6*Pesos!$H$5+Resultados!E7*Pesos!$H$6+Resultados!E8*Pesos!$H$7 -> 0.64280692 | D3: =Resultados!F5*Pesos!$H$4+Resultados!F6*Pesos!$H$5+Resultados!F7*Pesos!$H$6+Resultados!F8*Pesos!$H$7 -> 0.69403934 | E3: =Resultados!G5*Pesos!$H$4+Resultados!G6*Pesos!$H$5+Resultados!G7*Pesos!$H$6+Resultados!G8*Pesos!$H$7 -> 0.6463265 | F3: =Resultados!H5*Pesos!$H$4+Resultados!H6*Pesos!$H$5+Resultados!H7*Pesos!$H$6+Resultados!H8*Pesos!$H$7 -> 0.63531888 | G3: =Resultados!I5*Pesos!$H$4+Resultados!I6*Pesos!$H$5+Resultados!I7*Pesos!$H$6+Resultados!I8*Pesos!$H$7 -> 0.34382539 | H3: =Resultados!J5*Pesos!$H$4+Resultados!J6*Pesos!$H$5+Resultados!J7*Pesos!$H$6+Resultados!J8*Pesos!$H$7 -> 0.71726883 | I3: =Resultados!K5*Pesos!$H$4+Resultados!K6*Pesos!$H$5+Resultados!K7*Pesos!$H$6+Resultados!K8*Pesos!$H$7 -> 0.62265356 | ... AJ3: =Resultados!AL5*Pesos!$H$4+Resultados!AL6*Pesos!$H$5+Resultados!AL7*Pesos!$H$6+Resultados!AL8*Pesos!$H$7 -> 0.34889433
A4: Ciclabilidade | B4: =Resultados!D9*Pesos!$H$9+Resultados!D14*Pesos!$H$11+Resultados!D17*Pesos!$H$12 -> 0.58237254 | C4: =Resultados!E9*Pesos!$H$9+Resultados!E14*Pesos!$H$11+Resultados!E17*Pesos!$H$12 -> 0.32379486 | D4: =Resultados!F9*Pesos!$H$9+Resultados!F14*Pesos!$H$11+Resultados!F17*Pesos!$H$12 -> 0.23468653 | E4: =Resultados!G9*Pesos!$H$9+Resultados!G14*Pesos!$H$11+Resultados!G17*Pesos!$H$12 -> 0.11212767 | F4: =Resultados!H9*Pesos!$H$9+Resultados!H14*Pesos!$H$11+Resultados!H17*Pesos!$H$12 -> 0.16322107 | G4: =Resultados!I9*Pesos!$H$9+Resultados!I14*Pesos!$H$11+Resultados!I17*Pesos!$H$12 -> 0.11864324 | H4: =Resultados!J9*Pesos!$H$9+Resultados!J14*Pesos!$H$11+Resultados!J17*Pesos!$H$12 -> 0.39685517 | I4: =Resultados!K9*Pesos!$H$9+Resultados!K14*Pesos!$H$11+Resultados!K17*Pesos!$H$12 -> 0.59150556 | ... AJ4: =Resultados!AL9*Pesos!$H$9+Resultados!AL14*Pesos!$H$11+Resultados!AL17*Pesos!$H$12 -> 0.07263256
A5: Transporte Público | B5: =Resultados!D20*Pesos!$H$14+Resultados!D23*Pesos!$H$15+Resultados!D27*Pesos!$H$16+Resultados!D31*Pesos!$H$17 -> 0.1746056 | C5: =Resultados!E20*Pesos!$H$14+Resultados!E23*Pesos!$H$15+Resultados!E27*Pesos!$H$16+Resultados!E31*Pesos!$H$17 -> 0.20976969 | D5: =Resultados!F20*Pesos!$H$14+Resultados!F23*Pesos!$H$15+Resultados!F27*Pesos!$H$16+Resultados!F31*Pesos!$H$17 -> 0.3657888 | E5: =Resultados!G20*Pesos!$H$14+Resultados!G23*Pesos!$H$15+Resultados!G27*Pesos!$H$16+Resultados!G31*Pesos!$H$17 -> 0.20350297 | F5: =Resultados!H20*Pesos!$H$14+Resultados!H23*Pesos!$H$15+Resultados!H27*Pesos!$H$16+Resultados!H31*Pesos!$H$17 -> 0.20309947 | G5: =Resultados!I20*Pesos!$H$14+Resultados!I23*Pesos!$H$15+Resultados!I27*Pesos!$H$16+Resultados!I31*Pesos!$H$17 -> 0.20296315 | H5: =Resultados!J20*Pesos!$H$14+Resultados!J23*Pesos!$H$15+Resultados!J27*Pesos!$H$16+Resultados!J31*Pesos!$H$17 -> 0.27364417 | I5: =Resultados!K20*Pesos!$H$14+Resultados!K23*Pesos!$H$15+Resultados!K27*Pesos!$H$16+Resultados!K31*Pesos!$H$17 -> 0.43180371 | ... AJ5: =Resultados!AL20*Pesos!$H$14+Resultados!AL23*Pesos!$H$15+Resultados!AL27*Pesos!$H$16+Resultados!AL31*Pesos!$H$17 -> 0.33991763
A6: Proximidade Territorial | B6: =Resultados!D32*Pesos!$H$19+Resultados!D33*Pesos!$H$20+Resultados!D34*Pesos!$H$21+Resultados!D35*Pesos!$H$22 -> 0.8820616 | C6: =Resultados!E32*Pesos!$H$19+Resultados!E33*Pesos!$H$20+Resultados!E34*Pesos!$H$21+Resultados!E35*Pesos!$H$22 -> 0.66007416 | D6: =Resultados!F32*Pesos!$H$19+Resultados!F33*Pesos!$H$20+Resultados!F34*Pesos!$H$21+Resultados!F35*Pesos!$H$22 -> 0.71006698 | E6: =Resultados!G32*Pesos!$H$19+Resultados!G33*Pesos!$H$20+Resultados!G34*Pesos!$H$21+Resultados!G35*Pesos!$H$22 -> 0.60577862 | F6: =Resultados!H32*Pesos!$H$19+Resultados!H33*Pesos!$H$20+Resultados!H34*Pesos!$H$21+Resultados!H35*Pesos!$H$22 -> 0.5497535 | G6: =Resultados!I32*Pesos!$H$19+Resultados!I33*Pesos!$H$20+Resultados!I34*Pesos!$H$21+Resultados!I35*Pesos!$H$22 -> 0.68231736 | H6: =Resultados!J32*Pesos!$H$19+Resultados!J33*Pesos!$H$20+Resultados!J34*Pesos!$H$21+Resultados!J35*Pesos!$H$22 -> 0.52456414 | I6: =Resultados!K32*Pesos!$H$19+Resultados!K33*Pesos!$H$20+Resultados!K34*Pesos!$H$21+Resultados!K35*Pesos!$H$22 -> 0.46840176 | ... AJ6: =Resultados!AL32*Pesos!$H$19+Resultados!AL33*Pesos!$H$20+Resultados!AL34*Pesos!$H$21+Resultados!AL35*Pesos!$H$22 -> 0.28355032
A7: Aspectos Ambientais | B7: =Resultados!D37*Pesos!$H$24+Resultados!D38*Pesos!$H$25+Resultados!D39*Pesos!$H$26 -> 0.903632 | C7: =Resultados!E37*Pesos!$H$24+Resultados!E38*Pesos!$H$25+Resultados!E39*Pesos!$H$26 -> 0.8010948 | D7: =Resultados!F37*Pesos!$H$24+Resultados!F38*Pesos!$H$25+Resultados!F39*Pesos!$H$26 -> 0.8177388 | E7: =Resultados!G37*Pesos!$H$24+Resultados!G38*Pesos!$H$25+Resultados!G39*Pesos!$H$26 -> 0.7523792 | F7: =Resultados!H37*Pesos!$H$24+Resultados!H38*Pesos!$H$25+Resultados!H39*Pesos!$H$26 -> 0.6705912 | G7: =Resultados!I37*Pesos!$H$24+Resultados!I38*Pesos!$H$25+Resultados!I39*Pesos!$H$26 -> 0.672172 | H7: =Resultados!J37*Pesos!$H$24+Resultados!J38*Pesos!$H$25+Resultados!J39*Pesos!$H$26 -> 0.8369692 | I7: =Resultados!K37*Pesos!$H$24+Resultados!K38*Pesos!$H$25+Resultados!K39*Pesos!$H$26 -> 0.8370888 | ... AH7: =Resultados!AJ37*Pesos!$H$24+Resultados!AJ38*Pesos!$H$25+Resultados!AJ39*Pesos!$H$26 -> 0.6132896 | AI7: =Resultados!AK37*Pesos!$H$24+Resultados!AK38*Pesos!$I$25+Resultados!AK39*Pesos!$I$26 -> 0.48520489 | AJ7: =Resultados!AL37*Pesos!$H$24+Resultados!AL38*Pesos!$I$25+Resultados!AL39*Pesos!$I$26 -> 0.40665452
A8: IMAP | B8: =B3*Pesos!$H$3+B4*Pesos!$H$8+B5*Pesos!$H$13+B6*Pesos!$H$18+B7*Pesos!$H$23 -> 0.64641076 | C8: =C3*Pesos!$H$3+C4*Pesos!$H$8+C5*Pesos!$H$13+C6*Pesos!$H$18+C7*Pesos!$H$23 -> 0.52892573 | D8: =D3*Pesos!$H$3+D4*Pesos!$H$8+D5*Pesos!$H$13+D6*Pesos!$H$18+D7*Pesos!$H$23 -> 0.59496553 | E8: =E3*Pesos!$H$3+E4*Pesos!$H$8+E5*Pesos!$H$13+E6*Pesos!$H$18+E7*Pesos!$H$23 -> 0.49062137 | F8: =F3*Pesos!$H$3+F4*Pesos!$H$8+F5*Pesos!$H$13+F6*Pesos!$H$18+F7*Pesos!$H$23 -> 0.46281808 | G8: =G3*Pesos!$H$3+G4*Pesos!$H$8+G5*Pesos!$H$13+G6*Pesos!$H$18+G7*Pesos!$H$23 -> 0.43982035 | H8: =H3*Pesos!$H$3+H4*Pesos!$H$8+H5*Pesos!$H$13+H6*Pesos!$H$18+H7*Pesos!$H$23 -> 0.53077554 | I8: =I3*Pesos!$H$3+I4*Pesos!$H$8+I5*Pesos!$H$13+I6*Pesos!$H$18+I7*Pesos!$H$23 -> 0.55076778 | ... AJ8: =AJ3*Pesos!$H$3+AJ4*Pesos!$H$8+AJ5*Pesos!$H$13+AJ6*Pesos!$H$18+AJ7*Pesos!$H$23 -> 0.3166582

Sheet Resultados IMAP - ranking
A2: RA | C2: Caminhabilidade | D2: Ciclabilidade | E2: Transporte Público | F2: Proximidade Territorial | G2: Aspectos Ambientais | H2: IMAP
A3: RA XX | B3: Águas Claras | C3: 0.82751446 | D3: 0.83433416 | E3: 0.49865563 | F3: 0.53861496 | G3: 0.8297804 | H3: 0.64832358
A4: RA I | B4: Plano Piloto | C4: 0.77779563 | D4: 0.58237254 | E4: 0.1746056 | F4: 0.8820616 | G4: 0.903632 | H4: 0.64641076
A5: RA XXII | B5: Sudoeste - Octogonal | C5: 0.80846217 | D5: 0.8412942 | E5: 0.30258398 | F5: 0.52107358 | G5: 0.9319132 | H5: 0.5992478
A6: RA III | B6: Taguatinga | C6: 0.69403934 | D6: 0.23468653 | E6: 0.3657888 | F6: 0.71006698 | G6: 0.8177388 | H6: 0.59496553
A7: RA IX | B7: Ceilândia | C7: 0.71719687 | D7: 0.43259091 | E7: 0.33874577 | F7: 0.64271578 | G7: 0.8888624 | H7: 0.59469594
A8: RA XI | B8: Cruzeiro | C8: 0.70440695 | D8: 0.36417864 | E8: 0.38466852 | F8: 0.5261443 | G8: 0.9227336 | H8: 0.56963177
A9: RA VIII | B9: Nucleo Bandeirante | C9: 0.62265356 | D9: 0.59150556 | E9: 0.43180371 | F9: 0.46840176 | G9: 0.8370888 | H9: 0.55076778
A10: RA XXI | B10: Riacho Fundo II | C10: 0.75883448 | D10: 0.50073697 | E10: 0.42085536 | F10: 0.39645452 | G10: 0.8013244 | H10: 0.54313021
A11: RA XII | B11: Samambaia | C11: 0.66246691 | D11: 0.31718616 | E11: 0.36551261 | F11: 0.51571212 | G11: 0.79456 | H11: 0.5310769
A12: RA VII | B12: Paranoá | C12: 0.71726883 | D12: 0.39685517 | E12: 0.27364417 | F12: 0.52456414 | G12: 0.8369692 | H12: 0.53077554
A13: RA II | B13: Gama | C13: 0.64280692 | D13: 0.32379486 | E13: 0.20976969 | F13: 0.66007416 | G13: 0.8010948 | H13: 0.52892573
A14: RA X | B14: Guará | C14: 0.64761148 | D14: 0.56523879 | E14: 0.361243 | F14: 0.45037382 | G14: 0.7948996 | H14: 0.52306134
... A37: RA XXXV | B37: Água Quente | C37: 0.34889433 | D37: 0.07263256 | E37: 0.33991763 | F37: 0.28355032 | G37: 0.40665452 | H37: 0.3166582

Sheet Lorenz IMAP
A2: RA | C2: Caminhabilidade | D2: Ciclabilidade | E2: Transporte Público | F2: Proximidade Territorial | G2: Aspectos Ambientais | H2: IMAP | K2: curva de lorenz | L2: Gini | O2: Curva de Lorenz | P2: Gini | S2: igualdade perfeita
A3: RA XXXV | B3: Água Quente | C3: 0.34889433 | D3: 0.07263256 | E3: 0.33991763 | F3: 0.28355032 | G3: 0.40665452 | H3: 0.3166582 | J3: 0 | K3: 0 | L3: Cálculo das áreas | N3: =J3/$J$38 -> 0 | O3: =K3/$K$38 -> 0 | P3: Cálculo das áreas | R3: 0 | S3: 0
A4: RA XXXII | B4: Sol Nascente e Pôr do Sol | C4: 0.40036254 | D4: 0.050792 | E4: 0.31248449 | F4: 0.32356594 | G4: 0.5441756 | H4: 0.35006656 | J4: 1 | K4: =H3 -> 0.3166582 | L4: =(K4+K3)/2*(J4-J3) -> 0.1583291 | N4: =J4/$J$38 -> 0.028571429 | O4: =K4/$K$38 -> 0.01865012 | P4: =(O4+O3)/2*(N4-N3) -> 0.00026643028 | R4: 35 | S4: 16.978883
A5: RA XXIV | B5: Parkway | C5: 0.54556701 | D5: 0.46555953 | E5: 0.11883096 | F5: 0.31805712 | G5: 0.5518084 | H5: 0.35269909 | J5: 2 | K5: =K4+H4 -> 0.66672475 | L5: =(K5+K4)/2*(J5-J4) -> 0.49169147 | N5: =J5/$J$38 -> 0.057142857 | O5: =K5/$K$38 -> 0.039267881 | P5: =(O5+O4)/2*(N5-N4) -> 0.00082740001
A6: RA XXVII | B6: Jardim Botânico | C6: 0.67786735 | D6: 0.32567026 | E6: 0.11852622 | F6: 0.26207216 | G6: 0.6529552 | H6: 0.36836051 | J6: 3 | K6: =K5+H5 -> 1.0194238 | L6: =(K6+K5)/2*(J6-J5) -> 0.8430743 | N6: =J6/$J$38 -> 0.085714286 | O6: =K6/$K$38 -> 0.06004069 | P6: =(O6+O5)/2*(N6-N5) -> 0.0014186939
A7: RA XXXIV | B7: Arapoanga | C7: 0.27657686 | D7: 0.12385713 | E7: 0.35827353 | F7: 0.47493014 | G7: 0.48520489 | H7: 0.379625 | J7: 4 | K7: =K6+H6 -> 1.3877843 | L7: =(K7+K6)/2*(J7-J6) -> 1.2036041 | N7: =J7/$J$38 -> 0.11428571 | O7: =K7/$K$38 -> 0.081735904 | P7: =(O7+O6)/2*(N7-N6) -> 0.0020253799
A8: RA XXXI | B8: Fercal | C8: 0.28688463 | D8: 0.021049953 | E8: 0.28456926 | F8: 0.43910988 | G8: 0.7707044 | H8: 0.38416217 | J8: 5 | K8: =K7+H7 -> 1.7674094 | L8: =(K8+K7)/2*(J8-J7) -> 1.5775968 | N8: =J8/$J$38 -> 0.14285714 | O8: =K8/$K$38 -> 0.10409456 | P8: =(O8+O7)/2*(N8-N7) -> 0.0026547209 | S8: igualdade perfeita
A9: RA XXIX | B9: SIA | C9: 0.36000342 | D9: 0.21553232 | E9: 0.38374294 | F9: 0.40998916 | G9: 0.6763344 | H9: 0.41744644 | J9: 6 | K9: =K8+H8 -> 2.1515715 | L9: =(K9+K8)/2*(J9-J8) -> 1.9594904 | N9: =J9/$J$38 -> 0.17142857 | O9: =K9/$K$38 -> 0.12672044 | P9: =(O9+O8)/2*(N9-N8) -> 0.0032973572 | R9: 0 | S9: 0
A10: RA XXVI | B10: Sobradinho II | C10: 0.37886685 | D10: 0.11582387 | E10: 0.26832282 | F10: 0.5267706 | G10: 0.6718804 | H10: 0.41766985 | J10: 7 | K10: =K9+H9 -> 2.569018 | L10: =(K10+K9)/2*(J10-J9) -> 2.3602947 | N10: =J10/$J$38 -> 0.2 | O10: =K10/$K$38 -> 0.15130665 | P10: =(O10+O9)/2*(N10-N9) -> 0.0039718156 | R10: 1 | S10: 1
A11: RA XVIII | B11: Lago Norte | C11: 0.55357906 | D11: 0.350954 | E11: 0.1683777 | F11: 0.46570116 | G11: 0.6988868 | H11: 0.42669989 | J11: 8 | K11: =K10+H10 -> 2.9866878 | L11: =(K11+K10)/2*(J11-J10) -> 2.7778529 | N11: =J11/$J$38 -> 0.22857143 | O11: =K11/$K$38 -> 0.17590603 | P11: =(O11+O10)/2*(N11-N10) -> 0.0046744669
A12: RA XVI | B12: Lago Sul | C12: 0.69076874 | D12: 0.49108711 | E12: 0.12990184 | F12: 0.38091464 | G12: 0.7073144 | H12: 0.4289995 | J12: 9 | K12: =K11+H11 -> 3.4133877 | L12: =(K12+K11)/2*(J12-J11) -> 3.2000378 | N12: =J12/$J$38 -> 0.25714286 | O12: =K12/$K$38 -> 0.20103724 | P12: =(O12+O11)/2*(N12-N11) -> 0.0053849038
A13: RA XXXIII | B13: Arniqueira | C13: 0.50227592 | D13: 0.18049263 | E13: 0.33916644 | F13: 0.4611922 | G13: 0.6132896 | H13: 0.4390274 | J13: 10 | K13: =K12+H12 -> 3.8423872 | L13: =(K13+K12)/2*(J13-J12) -> 3.6278875 | N13: =J13/$J$38 -> 0.28571429 | O13: =K13/$K$38 -> 0.22630389 | P13: =(O13+O12)/2*(N13-N12) -> 0.0061048732
A14: RA VI | B14: Planaltina | C14: 0.34382539 | D14: 0.11864324 | E14: 0.20296315 | F14: 0.68231736 | G14: 0.672172 | H14: 0.43982035 | J14: 11 | K14: =K13+H13 -> 4.2814146 | L14: =(K14+K13)/2*(J14-J13) -> 4.0619009 | N14: =J14/$J$38 -> 0.31428571 | O14: =K14/$K$38 -> 0.25216115 | P14: =(O14+O13)/2*(N14-N13) -> 0.0068352148
A15: RA XXVIII | B15: Itapoã | C15: 0.63674856 | D15: 0.27886533 | E15: 0.358588 | F15: 0.40412834 | G15: 0.4966464 | H15: 0.44487795 | J15: 12 | K15: =K14+H14 -> 4.721235 | L15: =(K15+K14)/2*(J15-J14) -> 4.5013248 | N15: =J15/$J$38 -> 0.34285714 | O15: =K15/$K$38 -> 0.27806511 | P15: =(O15+O14)/2*(N15-N14) -> 0.0075746608
A16: RA XXV | B16: SCIA - Estrutural | C16: 0.44021503 | D16: 0.1392733 | E16: 0.48167536 | F16: 0.46097592 | G16: 0.5439676 | H16: 0.45326542 | J16: 13 | K16: =K15+H15 -> 5.1661129 | L16: =(K16+K15)/2*(J16-J15) -> 4.9436739 | N16: =J16/$J$38 -> 0.37142857 | O16: =K16/$K$38 -> 0.30426695 | P16: =(O16+O15)/2*(N16-N15) -> 0.0083190294
A17: RA V | B17: Sobradinho | C17: 0.63531888 | D17: 0.16322107 | E17: 0.20309947 | F17: 0.5497535 | G17: 0.6705912 | H17: 0.46281808 | J17: 14 | K17: =K16+H16 -> 5.6193783 | L17: =(K17+K16)/2*(J17-J16) -> 5.3927456 | N17: =J17/$J$38 -> 0.4 | O17: =K17/$K$38 -> 0.33096278 | P17: =(O17+O16)/2*(N17-N16) -> 0.0090747104
A18: RA XXX | B18: Vicente Pires | C18: 0.52295864 | D18: 0.22210952 | E18: 0.3262219 | F18: 0.51269586 | G18: 0.6952252 | H18: 0.46980302 | J18: 15 | K18: =K17+H17 -> 6.0821964 | L18: =(K18+K17)/2*(J18-J17) -> 5.8507874 | N18: =J18/$J$38 -> 0.42857143 | O18: =K18/$K$38 -> 0.35822124 | P18: =(O18+O17)/2*(N18-N17) -> 0.009845486
A19: RA IV | B19: Brazlândia | C19: 0.6463265 | D19: 0.11212767 | E19: 0.20350297 | F19: 0.60577862 | G19: 0.7523792 | H19: 0.49062137 | J19: 16 | K19: =K18+H18 -> 6.5519994 | L19: =(K19+K18)/2*(J19-J18) -> 6.3170979 | N19: =J19/$J$38 -> 0.45714286 | O19: =K19/$K$38 -> 0.38589108 | P19: =(O19+O18)/2*(N19-N18) -> 0.010630176
A20: RA XIV | B20: São Sebastião | C20: 0.507031 | D20: 0.21263305 | E20: 0.30589878 | F20: 0.6240609 | G20: 0.737756 | H20: 0.50022767 | J20: 17 | K20: =K19+H19 -> 7.0426208 | L20: =(K20+K19)/2*(J20-J19) -> 6.7973101 | N20: =J20/$J$38 -> 0.48571429 | O20: =K20/$K$38 -> 0.41478705 | P20: =(O20+O19)/2*(N20-N19) -> 0.011438259
A21: RA XIII | B21: Santa Maria | C21: 0.66450627 | D21: 0.38792094 | E21: 0.3647228 | F21: 0.47654294 | G21: 0.6321712 | H21: 0.50084836 | J21: 18 | K21: =K20+H20 -> 7.5428485 | L21: =(K21+K20)/2*(J21-J20) -> 7.2927346 | N21: =J21/$J$38 -> 0.51428571 | O21: =K21/$K$38 -> 0.44424881 | P21: =(O21+O20)/2*(N21-N20) -> 0.012271941
A22: RA XIX | B22: Candangolândia | C22: 0.6593966 | D22: 0.40651641 | E22: 0.33518156 | F22: 0.46033992 | G22: 0.7942152 | H22: 0.51084442 | J22: 19 | K22: =K21+H21 -> 8.0436968 | L22: =(K22+K21)/2*(J22-J21) -> 7.7932727 | N22: =J22/$J$38 -> 0.54285714 | O22: =K22/$K$38 -> 0.47374712 | P22: =(O22+O21)/2*(N22-N21) -> 0.013114227
... A37: RA XX | B37: Águas Claras | C37: 0.82751446 | D37: 0.83433416 | E37: 0.49865563 | F37: 0.53861496 | G37: 0.8297804 | H37: 0.64832358 | J37: 34 | K37: =K36+H36 -> 16.330559 | L37: =(K37+K36)/2*(J37-J36) -> 16.007354 | N37: =J37/$J$38 -> 0.97142857 | O37: =K37/$K$38 -> 0.96181589 | P37: =(O37+O36)/2*(N37-N36) -> 0.026936576
J38: 35 | K38: =K37+H37 -> 16.978883 | L38: =(K38+K37)/2*(J38-J37) -> 16.654721 | N38: =J38/$J$38 -> 1 | O38: =K38/$K$38 -> 1 | P38: =(O38+O37)/2*(N38-N37) -> 0.028025941
L39: =SUM(L4:L38) -> 268.33282 | P39: =SUM(P4:P38) -> 0.45154043
K41: Índice de Gini | L41: =1-(L39/(J38*K38/2)) -> 0.096919141 | O41: Índice de Gini | P41: =1-P39/0.5 -> 0.096919141
K43: A= | L43: =(J38*K38/2)-L39 -> 28.797628
L44: =L43/(J38*K38/2) -> 0.096919141
L46: =L43/(J38*K38/2) -> 0.096919141

Sheet Lorenz Caminhabilidade
A2: RA | C2: Caminhabilidade | D2: Ciclabilidade | E2: Transporte Público | F2: Proximidade Territorial | G2: Aspectos Ambientais | H2: IMAP | K2: curva de lorenz | L2: Gini | O2: Curva de Lorenz | P2: Gini | S2: igualdade perfeita
A3: RA XXXIV | B3: Arapoanga | C3: 0.27657686 | D3: 0.12385713 | E3: 0.35827353 | F3: 0.47493014 | G3: 0.48520489 | H3: 0.379625 | J3: 0 | K3: 0 | L3: Cálculo das áreas | N3: =J3/$J$38 -> 0 | O3: =K3/$K$38 -> 0 | P3: Cálculo das áreas | R3: 0 | S3: 0
A4: RA XXXI | B4: Fercal | C4: 0.28688463 | D4: 0.021049953 | E4: 0.28456926 | F4: 0.43910988 | G4: 0.7707044 | H4: 0.38416217 | J4: 1 | K4: =C3 -> 0.27657686 | L4: =(K4+K3)/2*(J4-J3) -> 0.13828843 | N4: =J4/$J$38 -> 0.028571429 | O4: =K4/$K$38 -> 0.013493544 | P4: =(O4+O3)/2*(N4-N3) -> 0.00019276491 | R4: 35 | S4: =K38 -> 20.496977
A5: RA VI | B5: Planaltina | C5: 0.34382539 | D5: 0.11864324 | E5: 0.20296315 | F5: 0.68231736 | G5: 0.672172 | H5: 0.43982035 | J5: 2 | K5: =K4+C4 -> 0.56346148 | L5: =(K5+K4)/2*(J5-J4) -> 0.42001917 | N5: =J5/$J$38 -> 0.057142857 | O5: =K5/$K$38 -> 0.02748998 | P5: =(O5+O4)/2*(N5-N4) -> 0.00058547892
A6: RA XXXV | B6: Água Quente | C6: 0.34889433 | D6: 0.07263256 | E6: 0.33991763 | F6: 0.28355032 | G6: 0.40665452 | H6: 0.3166582 | J6: 3 | K6: =K5+C5 -> 0.90728687 | L6: =(K6+K5)/2*(J6-J5) -> 0.73537418 | N6: =J6/$J$38 -> 0.085714286 | O6: =K6/$K$38 -> 0.044264425 | P6: =(O6+O5)/2*(N6-N5) -> 0.0010250629
A7: RA XXIX | B7: SIA | C7: 0.36000342 | D7: 0.21553232 | E7: 0.38374294 | F7: 0.40998916 | G7: 0.6763344 | H7: 0.41744644 | J7: 4 | K7: =K6+C6 -> 1.2561812 | L7: =(K7+K6)/2*(J7-J6) -> 1.081734 | N7: =J7/$J$38 -> 0.11428571 | O7: =K7/$K$38 -> 0.06128617 | P7: =(O7+O6)/2*(N7-N6) -> 0.0015078656
A8: RA XXVI | B8: Sobradinho II | C8: 0.37886685 | D8: 0.11582387 | E8: 0.26832282 | F8: 0.5267706 | G8: 0.6718804 | H8: 0.41766985 | J8: 5 | K8: =K7+C7 -> 1.6161846 | L8: =(K8+K7)/2*(J8-J7) -> 1.4361829 | N8: =J8/$J$38 -> 0.14285714 | O8: =K8/$K$38 -> 0.078849903 | P8: =(O8+O7)/2*(N8-N7) -> 0.0020019439 | S8: igualdade perfeita
A9: RA XXXII | B9: Sol Nascente e Pôr do Sol | C9: 0.40036254 | D9: 0.050792 | E9: 0.31248449 | F9: 0.32356594 | G9: 0.5441756 | H9: 0.35006656 | J9: 6 | K9: =K8+C8 -> 1.9950515 | L9: =(K9+K8)/2*(J9-J8) -> 1.805618 | N9: =J9/$J$38 -> 0.17142857 | O9: =K9/$K$38 -> 0.097333939 | P9: =(O9+O8)/2*(N9-N8) -> 0.002516912 | R9: 0 | S9: 0
A10: RA XXV | B10: SCIA - Estrutural | C10: 0.44021503 | D10: 0.1392733 | E10: 0.48167536 | F10: 0.46097592 | G10: 0.5439676 | H10: 0.45326542 | J10: 7 | K10: =K9+C9 -> 2.395414 | L10: =(K10+K9)/2*(J10-J9) -> 2.1952327 | N10: =J10/$J$38 -> 0.2 | O10: =K10/$K$38 -> 0.1168667 | P10: =(O10+O9)/2*(N10-N9) -> 0.0030600091 | R10: 1 | S10: 1
A11: RA XXXIII | B11: Arniqueira | C11: 0.50227592 | D11: 0.18049263 | E11: 0.33916644 | F11: 0.4611922 | G11: 0.6132896 | H11: 0.4390274 | J11: 8 | K11: =K10+C10 -> 2.835629 | L11: =(K11+K10)/2*(J11-J10) -> 2.6155215 | N11: =J11/$J$38 -> 0.22857143 | O11: =K11/$K$38 -> 0.13834377 | P11: =(O11+O10)/2*(N11-N10) -> 0.0036458639
A12: RA XIV | B12: São Sebastião | C12: 0.507031 | D12: 0.21263305 | E12: 0.30589878 | F12: 0.6240609 | G12: 0.737756 | H12: 0.50022767 | J12: 9 | K12: =K11+C11 -> 3.337905 | L12: =(K12+K11)/2*(J12-J11) -> 3.086767 | N12: =J12/$J$38 -> 0.25714286 | O12: =K12/$K$38 -> 0.16284865 | P12: =(O12+O11)/2*(N12-N11) -> 0.0043027489
A13: RA XXX | B13: Vicente Pires | C13: 0.52295864 | D13: 0.22210952 | E13: 0.3262219 | F13: 0.51269586 | G13: 0.6952252 | H13: 0.46980302 | J13: 10 | K13: =K12+C12 -> 3.844936 | L13: =(K13+K12)/2*(J13-J12) -> 3.5914205 | N13: =J13/$J$38 -> 0.28571429 | O13: =K13/$K$38 -> 0.18758552 | P13: =(O13+O12)/2*(N13-N12) -> 0.0050062024
A14: RA XXIV | B14: Parkway | C14: 0.54556701 | D14: 0.46555953 | E14: 0.11883096 | F14: 0.31805712 | G14: 0.5518084 | H14: 0.35269909 | J14: 11 | K14: =K13+C13 -> 4.3678946 | L14: =(K14+K13)/2*(J14-J13) -> 4.1064153 | N14: =J14/$J$38 -> 0.31428571 | O14: =K14/$K$38 -> 0.21309946 | P14: =(O14+O13)/2*(N14-N13) -> 0.0057240711
A15: RA XVIII | B15: Lago Norte | C15: 0.55357906 | D15: 0.350954 | E15: 0.1683777 | F15: 0.46570116 | G15: 0.6988868 | H15: 0.42669989 | J15: 12 | K15: =K14+C14 -> 4.9134616 | L15: =(K15+K14)/2*(J15-J14) -> 4.6406781 | N15: =J15/$J$38 -> 0.34285714 | O15: =K15/$K$38 -> 0.23971641 | P15: =(O15+O14)/2*(N15-N14) -> 0.0064687981
A16: RA XXIII | B16: Varjão | C16: 0.56374322 | D16: 0.26198499 | E16: 0.5049218 | F16: 0.393015 | G16: 0.8797628 | H16: 0.52049124 | J16: 13 | K16: =K15+C15 -> 5.4670407 | L16: =(K16+K15)/2*(J16-J15) -> 5.1902511 | N16: =J16/$J$38 -> 0.37142857 | O16: =K16/$K$38 -> 0.26672425 | P16: =(O16+O15)/2*(N16-N15) -> 0.0072348665
A17: RA XV | B17: Recanto das Emas | C17: 0.58336841 | D17: 0.42715465 | E17: 0.33803071 | F17: 0.55129634 | G17: 0.7614304 | H17: 0.52023996 | J17: 14 | K17: =K16+C16 -> 6.0307839 | L17: =(K17+K16)/2*(J17-J16) -> 5.7489123 | N17: =J17/$J$38 -> 0.4 | O17: =K17/$K$38 -> 0.29422797 | P17: =(O17+O16)/2*(N17-N16) -> 0.0080136032
A18: RA VIII | B18: Nucleo Bandeirante | C18: 0.62265356 | D18: 0.59150556 | E18: 0.43180371 | F18: 0.46840176 | G18: 0.8370888 | H18: 0.55076778 | J18: 15 | K18: =K17+C17 -> 6.6141523 | L18: =(K18+K17)/2*(J18-J17) -> 6.3224681 | N18: =J18/$J$38 -> 0.42857143 | O18: =K18/$K$38 -> 0.32268917 | P18: =(O18+O17)/2*(N18-N17) -> 0.008813102
A19: RA V | B19: Sobradinho | C19: 0.63531888 | D19: 0.16322107 | E19: 0.20309947 | F19: 0.5497535 | G19: 0.6705912 | H19: 0.46281808 | J19: 16 | K19: =K18+C18 -> 7.2368058 | L19: =(K19+K18)/2*(J19-J18) -> 6.9254791 | N19: =J19/$J$38 -> 0.45714286 | O19: =K19/$K$38 -> 0.35306699 | P19: =(O19+O18)/2*(N19-N18) -> 0.0096536594
A20: RA XXVIII | B20: Itapoã | C20: 0.63674856 | D20: 0.27886533 | E20: 0.358588 | F20: 0.40412834 | G20: 0.4966464 | H20: 0.44487795 | J20: 17 | K20: =K19+C19 -> 7.8721247 | L20: =(K20+K19)/2*(J20-J19) -> 7.5544653 | N20: =J20/$J$38 -> 0.48571429 | O20: =K20/$K$38 -> 0.38406273 | P20: =(O20+O19)/2*(N20-N19) -> 0.010530425
A21: RA II | B21: Gama | C21: 0.64280692 | D21: 0.32379486 | E21: 0.20976969 | F21: 0.66007416 | G21: 0.8010948 | H21: 0.52892573 | J21: 18 | K21: =K20+C20 -> 8.5088733 | L21: =(K21+K20)/2*(J21-J20) -> 8.190499 | N21: =J21/$J$38 -> 0.51428571 | O21: =K21/$K$38 -> 0.41512822 | P21: =(O21+O20)/2*(N21-N20) -> 0.011417013
A22: RA IV | B22: Brazlândia | C22: 0.6463265 | D22: 0.11212767 | E22: 0.20350297 | F22: 0.60577862 | G22: 0.7523792 | H22: 0.49062137 | J22: 19 | K22: =K21+C21 -> 9.1516802 | L22: =(K22+K21)/2*(J22-J21) -> 8.8302768 | N22: =J22/$J$38 -> 0.54285714 | O22: =K22/$K$38 -> 0.44648928 | P22: =(O22+O21)/2*(N22-N21) -> 0.012308821
... A37: RA XX | B37: Águas Claras | C37: 0.82751446 | D37: 0.83433416 | E37: 0.49865563 | F37: 0.53861496 | G37: 0.8297804 | H37: 0.64832358 | J37: 34 | K37: =K36+C36 -> 19.669462 | L37: =(K37+K36)/2*(J37-J36) -> 19.265231 | N37: =J37/$J$38 -> 0.97142857 | O37: =K37/$K$38 -> 0.95962749 | P37: =(O37+O36)/2*(N37-N36) -> 0.026854457
J38: 35 | K38: =K37+C37 -> 20.496977 | L38: =(K38+K37)/2*(J38-J37) -> 20.083219 | N38: =J38/$J$38 -> 1 | O38: =K38/$K$38 -> 1 | P38: =(O38+O37)/2*(N38-N37) -> 0.027994678
L39: =SUM(L4:L38) -> 308.01052 | P39: =SUM(P4:P38) -> 0.42934627
K41: Índice de Gini | L41: =1-(L39/(J38*K38/2)) -> 0.14130745 | O41: Índice de Gini | P41: =1-P39/0.5 -> 0.14130745
K43: A= | L43: =(J38*K38/2)-L39 -> 50.686573
L44: =L43/(J38*K38/2) -> 0.14130745
L46: =L43/(J38*K38/2) -> 0.14130745

Sheet Lorenz Ciclabilidade
A2: RA | C2: Caminhabilidade | D2: Ciclabilidade | E2: Transporte Público | F2: Proximidade Territorial | G2: Aspectos Ambientais | H2: IMAP | K2: curva de lorenz | L2: Gini | O2: Curva de Lorenz | P2: Gini | S2: igualdade perfeita
A3: RA XXXI | B3: Fercal | C3: 0.28688463 | D3: 0.021049953 | E3: 0.28456926 | F3: 0.43910988 | G3: 0.7707044 | H3: 0.38416217 | J3: 0 | K3: 0 | L3: Cálculo das áreas | N3: =J3/$J$38 -> 0 | O3: =K3/$K$38 -> 0 | P3: Cálculo das áreas | R3: 0 | S3: 0
A4: RA XXXII | B4: Sol Nascente e Pôr do Sol | C4: 0.40036254 | D4: 0.050792 | E4: 0.31248449 | F4: 0.32356594 | G4: 0.5441756 | H4: 0.35006656 | J4: 1 | K4: =D3 -> 0.021049953 | L4: =(K4+K3)/2*(J4-J3) -> 0.010524976 | N4: =J4/$J$38 -> 0.028571429 | O4: =K4/$K$38 -> 0.001849891 | P4: =(O4+O3)/2*(N4-N3) -> 2.6427015e-05 | R4: 35 | S4: =K38 -> 11.379023
A5: RA XXXV | B5: Água Quente | C5: 0.34889433 | D5: 0.07263256 | E5: 0.33991763 | F5: 0.28355032 | G5: 0.40665452 | H5: 0.3166582 | J5: 2 | K5: =K4+D4 -> 0.071841953 | L5: =(K5+K4)/2*(J5-J4) -> 0.046445953 | N5: =J5/$J$38 -> 0.057142857 | O5: =K5/$K$38 -> 0.0063135432 | P5: =(O5+O4)/2*(N5-N4) -> 0.00011662049
A6: RA IV | B6: Brazlândia | C6: 0.6463265 | D6: 0.11212767 | E6: 0.20350297 | F6: 0.60577862 | G6: 0.7523792 | H6: 0.49062137 | J6: 3 | K6: =K5+D5 -> 0.14447451 | L6: =(K6+K5)/2*(J6-J5) -> 0.10815823 | N6: =J6/$J$38 -> 0.085714286 | O6: =K6/$K$38 -> 0.012696566 | P6: =(O6+O5)/2*(N6-N5) -> 0.00027157298
A7: RA XXVI | B7: Sobradinho II | C7: 0.37886685 | D7: 0.11582387 | E7: 0.26832282 | F7: 0.5267706 | G7: 0.6718804 | H7: 0.41766985 | J7: 4 | K7: =K6+D6 -> 0.25660218 | L7: =(K7+K6)/2*(J7-J6) -> 0.20053835 | N7: =J7/$J$38 -> 0.11428571 | O7: =K7/$K$38 -> 0.022550458 | P7: =(O7+O6)/2*(N7-N6) -> 0.00050352891
A8: RA VI | B8: Planaltina | C8: 0.34382539 | D8: 0.11864324 | E8: 0.20296315 | F8: 0.68231736 | G8: 0.672172 | H8: 0.43982035 | J8: 5 | K8: =K7+D7 -> 0.37242605 | L8: =(K8+K7)/2*(J8-J7) -> 0.31451411 | N8: =J8/$J$38 -> 0.14285714 | O8: =K8/$K$38 -> 0.032729176 | P8: =(O8+O7)/2*(N8-N7) -> 0.00078970906 | S8: igualdade perfeita
A9: RA XXXIV | B9: Arapoanga | C9: 0.27657686 | D9: 0.12385713 | E9: 0.35827353 | F9: 0.47493014 | G9: 0.48520489 | H9: 0.379625 | J9: 6 | K9: =K8+D8 -> 0.49106929 | L9: =(K9+K8)/2*(J9-J8) -> 0.43174767 | N9: =J9/$J$38 -> 0.17142857 | O9: =K9/$K$38 -> 0.043155664 | P9: =(O9+O8)/2*(N9-N8) -> 0.0010840691 | R9: 0 | S9: 0
A10: RA XXV | B10: SCIA - Estrutural | C10: 0.44021503 | D10: 0.1392733 | E10: 0.48167536 | F10: 0.46097592 | G10: 0.5439676 | H10: 0.45326542 | J10: 7 | K10: =K9+D9 -> 0.61492642 | L10: =(K10+K9)/2*(J10-J9) -> 0.55299785 | N10: =J10/$J$38 -> 0.2 | O10: =K10/$K$38 -> 0.054040353 | P10: =(O10+O9)/2*(N10-N9) -> 0.0013885145 | R10: 1 | S10: 1
A11: RA V | B11: Sobradinho | C11: 0.63531888 | D11: 0.16322107 | E11: 0.20309947 | F11: 0.5497535 | G11: 0.6705912 | H11: 0.46281808 | J11: 8 | K11: =K10+D10 -> 0.75419972 | L11: =(K11+K10)/2*(J11-J10) -> 0.68456307 | N11: =J11/$J$38 -> 0.22857143 | O11: =K11/$K$38 -> 0.066279831 | P11: =(O11+O10)/2*(N11-N10) -> 0.0017188598
A12: RA XXXIII | B12: Arniqueira | C12: 0.50227592 | D12: 0.18049263 | E12: 0.33916644 | F12: 0.4611922 | G12: 0.6132896 | H12: 0.4390274 | J12: 9 | K12: =K11+D11 -> 0.9174208 | L12: =(K12+K11)/2*(J12-J11) -> 0.83581026 | N12: =J12/$J$38 -> 0.25714286 | O12: =K12/$K$38 -> 0.080623864 | P12: =(O12+O11)/2*(N12-N11) -> 0.0020986242
A13: RA XIV | B13: São Sebastião | C13: 0.507031 | D13: 0.21263305 | E13: 0.30589878 | F13: 0.6240609 | G13: 0.737756 | H13: 0.50022767 | J13: 10 | K13: =K12+D12 -> 1.0979134 | L13: =(K13+K12)/2*(J13-J12) -> 1.0076671 | N13: =J13/$J$38 -> 0.28571429 | O13: =K13/$K$38 -> 0.096485738 | P13: =(O13+O12)/2*(N13-N12) -> 0.0025301372
A14: RA XXIX | B14: SIA | C14: 0.36000342 | D14: 0.21553232 | E14: 0.38374294 | F14: 0.40998916 | G14: 0.6763344 | H14: 0.41744644 | J14: 11 | K14: =K13+D13 -> 1.3105465 | L14: =(K14+K13)/2*(J14-J13) -> 1.2042299 | N14: =J14/$J$38 -> 0.31428571 | O14: =K14/$K$38 -> 0.11517214 | P14: =(O14+O13)/2*(N14-N13) -> 0.003023684
A15: RA XXX | B15: Vicente Pires | C15: 0.52295864 | D15: 0.22210952 | E15: 0.3262219 | F15: 0.51269586 | G15: 0.6952252 | H15: 0.46980302 | J15: 12 | K15: =K14+D14 -> 1.5260788 | L15: =(K15+K14)/2*(J15-J14) -> 1.4183126 | N15: =J15/$J$38 -> 0.34285714 | O15: =K15/$K$38 -> 0.13411334 | P15: =(O15+O14)/2*(N15-N14) -> 0.0035612212
A16: RA III | B16: Taguatinga | C16: 0.69403934 | D16: 0.23468653 | E16: 0.3657888 | F16: 0.71006698 | G16: 0.8177388 | H16: 0.59496553 | J16: 13 | K16: =K15+D15 -> 1.7481883 | L16: =(K16+K15)/2*(J16-J15) -> 1.6371335 | N16: =J16/$J$38 -> 0.37142857 | O16: =K16/$K$38 -> 0.15363255 | P16: =(O16+O15)/2*(N16-N15) -> 0.0041106556
A17: RA XVII | B17: Riacho Fundo | C17: 0.69083377 | D17: 0.25034693 | E17: 0.29839337 | F17: 0.52199968 | G17: 0.8422524 | H17: 0.5225976 | J17: 14 | K17: =K16+D16 -> 1.9828748 | L17: =(K17+K16)/2*(J17-J16) -> 1.8655316 | N17: =J17/$J$38 -> 0.4 | O17: =K17/$K$38 -> 0.17425704 | P17: =(O17+O16)/2*(N17-N16) -> 0.004684137
